Exception in Tkinter callback
Traceback (most recent call last):
  File "C:\Program Files\WindowsApps\PythonSoftwareFoundation.Python.3.12_3.12.2032.0_x64__qbz5n2kfra8p0\Lib\tkinter\__init__.py", line 1968, in __call__
    return self.func(*args)
           ^^^^^^^^^^^^^^^^
  File "C:\Users\User\OneDrive - student.newinti.edu.my\Carmala\main\User profile.py", line 72, in save_to_database
    user_id = logged_in_user["user_id"]
              ^^^^^^^^^^^^^^
NameError: name 'logged_in_user' is not defined. Did you mean: 'logged_in_user_id'?
Exception in Tkinter callback
Traceback (most recent call last):
  File "C:\Program Files\WindowsApps\PythonSoftwareFoundation.Python.3.12_3.12.2032.0_x64__qbz5n2kfra8p0\Lib\tkinter\__init__.py", line 1968, in __call__
    return self.func(*args)
           ^^^^^^^^^^^^^^^^
  File "C:\Users\User\OneDrive - student.newinti.edu.my\Carmala\main\User profile.py", line 72, in save_to_database
    user_id = logged_in_user["user_id"]
              ^^^^^^^^^^^^^^
NameError: name 'logged_in_user' is not defined. Did you mean: 'logged_in_user_id'?
Exception in Tkinter callback
Traceback (most recent call last):
  File "C:\Program Files\WindowsApps\PythonSoftwareFoundation.Python.3.12_3.12.2032.0_x64__qbz5n2kfra8p0\Lib\tkinter\__init__.py", line 1968, in __call__
    return self.func(*args)
           ^^^^^^^^^^^^^^^^
  File "C:\Users\User\OneDrive - student.newinti.edu.my\Carmala\main\User profile.py", line 72, in save_to_database
    user_id = logged_in_user["user_id"]
              ^^^^^^^^^^^^^^
NameError: name 'logged_in_user' is not defined. Did you mean: 'logged_in_user_id'?
Exception in Tkinter callback
Traceback (most recent call last):
  File "C:\Program Files\WindowsApps\PythonSoftwareFoundation.Python.3.12_3.12.2032.0_x64__qbz5n2kfra8p0\Lib\tkinter\__init__.py", line 1968, in __call__
    return self.func(*args)
           ^^^^^^^^^^^^^^^^
  File "C:\Users\User\OneDrive - student.newinti.edu.my\Carmala\main\User profile.py", line 72, in save_to_database
    user_id = logged_in_user["user_id"]
              ^^^^^^^^^^^^^^
NameError: name 'logged_in_user' is not defined. Did you mean: 'logged_in_user_id'?
Exception in Tkinter callback
Traceback (most recent call last):
  File "C:\Program Files\WindowsApps\PythonSoftwareFoundation.Python.3.12_3.12.2032.0_x64__qbz5n2kfra8p0\Lib\tkinter\__init__.py", line 1968, in __call__
    return self.func(*args)
           ^^^^^^^^^^^^^^^^
  File "C:\Users\User\OneDrive - student.newinti.edu.my\Carmala\main\User profile.py", line 72, in save_to_database
    user_id = logged_in_user["user_id"]
              ^^^^^^^^^^^^^^
NameError: name 'logged_in_user' is not defined. Did you mean: 'logged_in_user_id'?
Exception in Tkinter callback
Traceback (most recent call last):
  File "C:\Program Files\WindowsApps\PythonSoftwareFoundation.Python.3.12_3.12.2032.0_x64__qbz5n2kfra8p0\Lib\tkinter\__init__.py", line 1968, in __call__
    return self.func(*args)
           ^^^^^^^^^^^^^^^^
  File "C:\Users\User\OneDrive - student.newinti.edu.my\Carmala\main\User profile.py", line 72, in save_to_database
    user_id = logged_in_user["user_id"]
              ^^^^^^^^^^^^^^
NameError: name 'logged_in_user' is not defined. Did you mean: 'logged_in_user_id'?
Exception in Tkinter callback
Traceback (most recent call last):
  File "C:\Program Files\WindowsApps\PythonSoftwareFoundation.Python.3.12_3.12.2032.0_x64__qbz5n2kfra8p0\Lib\tkinter\__init__.py", line 1968, in __call__
    return self.func(*args)
           ^^^^^^^^^^^^^^^^
  File "C:\Users\User\OneDrive - student.newinti.edu.my\Carmala\main\User profile.py", line 72, in save_to_database
    user_id = logged_in_user["user_id"]
              ^^^^^^^^^^^^^^
NameError: name 'logged_in_user' is not defined. Did you mean: 'logged_in_user_id'?
Exception in Tkinter callback
Traceback (most recent call last):
  File "C:\Program Files\WindowsApps\PythonSoftwareFoundation.Python.3.12_3.12.2032.0_x64__qbz5n2kfra8p0\Lib\tkinter\__init__.py", line 1968, in __call__
    return self.func(*args)
           ^^^^^^^^^^^^^^^^
  File "C:\Users\User\OneDrive - student.newinti.edu.my\Carmala\main\User profile.py", line 72, in save_to_database
    user_id = logged_in_user["user_id"]
              ^^^^^^^^^^^^^^
NameError: name 'logged_in_user' is not defined. Did you mean: 'logged_in_user_id'?
Exception in Tkinter callback
Traceback (most recent call last):
  File "C:\Program Files\WindowsApps\PythonSoftwareFoundation.Python.3.12_3.12.2032.0_x64__qbz5n2kfra8p0\Lib\tkinter\__init__.py", line 1968, in __call__
    return self.func(*args)
           ^^^^^^^^^^^^^^^^
  File "C:\Users\User\OneDrive - student.newinti.edu.my\Carmala\main\User profile.py", line 72, in save_to_database
    user_id = logged_in_user["user_id"]
              ^^^^^^^^^^^^^^
NameError: name 'logged_in_user' is not defined. Did you mean: 'logged_in_user_id'?
